INFO:aiogram:Bot: my_main_bot [@eddi_kimBot]
WARNING:aiogram:Updates were skipped successfully.
INFO:aiogram.dispatcher.dispatcher:Start polling.
INFO:aiogram.dispatcher.dispatcher:Stop polling...
WARNING:aiogram:Goodbye!
Traceback (most recent call last):
  File "/home/sammy/myprojectdir/manage.py", line 22, in <module>
    main()
  File "/home/sammy/myprojectdir/manage.py", line 18, in main
    execute_from_command_line(sys.argv)
  File "/home/sammy/myprojectdir/myprojectenv/lib/python3.8/site-packages/django/core/management/__init__.py", line 419, in execute_from_command_line
    utility.execute()
  File "/home/sammy/myprojectdir/myprojectenv/lib/python3.8/site-packages/django/core/management/__init__.py", line 413, in execute
    self.fetch_command(subcommand).run_from_argv(self.argv)
  File "/home/sammy/myprojectdir/myprojectenv/lib/python3.8/site-packages/django/core/management/base.py", line 354, in run_from_argv
    self.execute(*args, **cmd_options)
  File "/home/sammy/myprojectdir/myprojectenv/lib/python3.8/site-packages/django/core/management/base.py", line 398, in execute
    output = self.handle(*args, **options)
  File "/home/sammy/myprojectdir/bot_app/management/commands/bot.py", line 10, in handle
    call(["python", '/home/sammy/myprojectdir/bot_app/management/commands/src/main.py'])
  File "/usr/lib/python3.8/subprocess.py", line 342, in call
    return p.wait(timeout=timeout)
  File "/usr/lib/python3.8/subprocess.py", line 1083, in wait
    return self._wait(timeout=timeout)
  File "/usr/lib/python3.8/subprocess.py", line 1806, in _wait
    (pid, sts) = self._try_wait(0)
  File "/usr/lib/python3.8/subprocess.py", line 1764, in _try_wait
    (pid, sts) = os.waitpid(self.pid, wait_flags)
KeyboardInterrupt
INFO:aiogram:Bot: my_main_bot [@eddi_kimBot]
WARNING:aiogram:Updates were skipped successfully.
INFO:aiogram.dispatcher.dispatcher:Start polling.
INFO:aiogram.dispatcher.dispatcher:Stop polling...
WARNING:aiogram:Goodbye!
Traceback (most recent call last):
  File "/home/sammy/myprojectdir/manage.py", line 22, in <module>
    main()
  File "/home/sammy/myprojectdir/manage.py", line 18, in main
    execute_from_command_line(sys.argv)
  File "/home/sammy/myprojectdir/myprojectenv/lib/python3.8/site-packages/django/core/management/__init__.py", line 419, in execute_from_command_line
    utility.execute()
  File "/home/sammy/myprojectdir/myprojectenv/lib/python3.8/site-packages/django/core/management/__init__.py", line 413, in execute
    self.fetch_command(subcommand).run_from_argv(self.argv)
  File "/home/sammy/myprojectdir/myprojectenv/lib/python3.8/site-packages/django/core/management/base.py", line 354, in run_from_argv
    self.execute(*args, **cmd_options)
  File "/home/sammy/myprojectdir/myprojectenv/lib/python3.8/site-packages/django/core/management/base.py", line 398, in execute
    output = self.handle(*args, **options)
  File "/home/sammy/myprojectdir/bot_app/management/commands/bot.py", line 10, in handle
    call(["python", '/home/sammy/myprojectdir/bot_app/management/commands/src/main.py'])
  File "/usr/lib/python3.8/subprocess.py", line 342, in call
    return p.wait(timeout=timeout)
  File "/usr/lib/python3.8/subprocess.py", line 1083, in wait
    return self._wait(timeout=timeout)
  File "/usr/lib/python3.8/subprocess.py", line 1806, in _wait
    (pid, sts) = self._try_wait(0)
  File "/usr/lib/python3.8/subprocess.py", line 1764, in _try_wait
    (pid, sts) = os.waitpid(self.pid, wait_flags)
KeyboardInterrupt
INFO:aiogram:Bot: my_main_bot [@eddi_kimBot]
WARNING:aiogram:Updates were skipped successfully.
INFO:aiogram.dispatcher.dispatcher:Start polling.
ERROR:aiogram.dispatcher.dispatcher:Cause exception while getting updates.
Traceback (most recent call last):
  File "/home/sammy/myprojectdir/myprojectenv/lib/python3.8/site-packages/aiogram/dispatcher/dispatcher.py", line 381, in start_polling
    updates = await self.bot.get_updates(
  File "/home/sammy/myprojectdir/myprojectenv/lib/python3.8/site-packages/aiogram/bot/bot.py", line 110, in get_updates
    result = await self.request(api.Methods.GET_UPDATES, payload)
  File "/home/sammy/myprojectdir/myprojectenv/lib/python3.8/site-packages/aiogram/bot/base.py", line 236, in request
    return await api.make_request(await self.get_session(), self.server, self.__token, method, data, files,
  File "/home/sammy/myprojectdir/myprojectenv/lib/python3.8/site-packages/aiogram/bot/api.py", line 140, in make_request
    return check_result(method, response.content_type, response.status, await response.text())
  File "/home/sammy/myprojectdir/myprojectenv/lib/python3.8/site-packages/aiogram/bot/api.py", line 111, in check_result
    raise exceptions.RetryAfter(parameters.retry_after)
aiogram.utils.exceptions.RetryAfter: Flood control exceeded. Retry in 5 seconds.
ERROR:aiogram.dispatcher.dispatcher:Cause exception while getting updates.
Traceback (most recent call last):
  File "/home/sammy/myprojectdir/myprojectenv/lib/python3.8/site-packages/aiogram/dispatcher/dispatcher.py", line 381, in start_polling
    updates = await self.bot.get_updates(
  File "/home/sammy/myprojectdir/myprojectenv/lib/python3.8/site-packages/aiogram/bot/bot.py", line 110, in get_updates
    result = await self.request(api.Methods.GET_UPDATES, payload)
  File "/home/sammy/myprojectdir/myprojectenv/lib/python3.8/site-packages/aiogram/bot/base.py", line 236, in request
    return await api.make_request(await self.get_session(), self.server, self.__token, method, data, files,
  File "/home/sammy/myprojectdir/myprojectenv/lib/python3.8/site-packages/aiogram/bot/api.py", line 140, in make_request
    return check_result(method, response.content_type, response.status, await response.text())
  File "/home/sammy/myprojectdir/myprojectenv/lib/python3.8/site-packages/aiogram/bot/api.py", line 128, in check_result
    raise exceptions.TelegramAPIError(description)
aiogram.utils.exceptions.TelegramAPIError: Bad Gateway
